<?xml version="1.0" ?>
<robot name="diff2">
  <material name="black">
    <color rgba="0.0 0.0 0.0 .9"/>
  </material>
  <material name="dark">
    <color rgba="0.3 0.3 0.3 .9"/>
  </material>
  <material name="light_black">
    <color rgba="0.4 0.4 0.4 .9"/>
  </material>
  <material name="blue">
    <color rgba="0.0 0.0 0.8 0.9"/>
  </material>
  <material name="green">
    <color rgba="0.0 0.8 0.0 0.9"/>
  </material>
  <material name="grey">
    <color rgba="0.5 0.5 0.5 0.9"/>
  </material>
  <material name="orange">
    <color rgba="1.0 0.4235 0.0392 0.9"/>
  </material>
  <material name="brown">
    <color rgba="0.8706 0.8118 0.7647 0.9"/>
  </material>
  <material name="red">
    <color rgba="0.8 0.0 0.0 0.9"/>
  </material>
  <material name="white">
    <color rgba="1.0 1.0 1.0 0.9"/>
  </material>

  <link name="base_footprint"/>

  <joint name="base_joint" type="fixed">
    <parent link="base_footprint"/>
    <child link="base_link" />
    <origin xyz="0 0 0.05" rpy="0 0 0"/>
  </joint>

  <link name="base_link">
    <visual>
      <origin xyz="0 0 0.03" rpy="0 0 0"/>
      <geometry>
        <box size=".15 .125 .01"/>
      </geometry>
      <material name="white"/>
    </visual>

    <collision>
      <origin xyz="0 0 0.03" rpy="0 0 0"/>
      <geometry>
        <box size=".15 .125 .01"/>
      </geometry>
      <contact_coefficients mu="0" kp="1000.0" kd="1.0"/>
    </collision>

    <inertial>
      <origin xyz="-0.1 0 0" rpy="0 0 0"/>
      <mass value="1.3729096e+00"/>
      <inertia ixx="8.7002718e-03" ixy="-4.7576583e-05" ixz="1.1160499e-04"
               iyy="8.6195418e-03" iyz="-3.5422299e-06"
               izz="1.4612727e-02" />
    </inertial>
  </link>

  <joint name="housing_joint" type="fixed">
    <parent link="base_link"/>
    <child link="housing_link" />
    <origin xyz="-0.01 0 0.06" rpy="0 0 0.0"/>
  </joint>

  <link name="housing_link">
    <visual>
      <origin xyz="0 0 .0" rpy="0 0 0"/>
      <geometry>
        <box size=".1 .1 .06"/>
      </geometry>
      <material name="orange"/>
    </visual>
    <collision>
      <origin xyz="0 0 .0" rpy="0 0 0"/>
      <geometry>
        <box size=".1 .01 .06"/>
      </geometry>
    </collision>
    <inertial>
      <origin xyz=".0 0 0" rpy="0 0 0"/>
      <mass value="0.01"/>
      <inertia ixx="8.7002718e-04" ixy="-4.7576583e-07" ixz="1.1160499e-07"
               iyy="8.6195418e-04" iyz="-3.5422299e-07"
               izz="1.4612727e-04" />
    </inertial>
  </link>

  <joint name="wheel_left_joint" type="continuous"> <!-- continuous -->
    <parent link="base_link"/>
    <child link="wheel_left_link"/>
    <origin xyz="0 0.085 -0.015" rpy="0 0 0"/>
    <axis xyz="0 1 0"/>
  </joint>

  <link name="wheel_left_link">
    <visual>
      <origin xyz="0 0 0" rpy="0 1.57079633 1.57079633"/>
      <geometry>
        <cylinder radius=".035" length=".025" />
        <!--<mesh filename="package://ros2_tutorial_urdf/meshes/wheels/wheel_assy.dae" scale="1 1 1"/>-->
      </geometry>
      <material name="dark"/>
    </visual>

    <collision>
      <origin xyz="0 0 0" rpy="0 1.57079633 1.57079633"/>
      <geometry>
        <cylinder radius=".035" length=".025" />
        <!--<mesh filename="package://ros2_tutorial_urdf/meshes/wheels/wheel_assy.dae" scale="1 1 1"/>-->
      </geometry>
    </collision>
    <inertial>
      <origin xyz="0 0 0" />
      <mass value="2.8498940e-02" />
      <inertia ixx="1.1175580e-05" ixy="-4.2369783e-11" ixz="-5.9381719e-09"
               iyy="1.1192413e-05" iyz="-1.4400107e-11"
               izz="2.0712558e-05" />
    </inertial>
  </link>

  <joint name="wheel_right_joint" type="continuous"> <!-- continuous -->
    <parent link="base_link"/>
    <child link="wheel_right_link"/>
    <origin xyz="0 -0.085 -0.015" rpy="0 0 0"/>
    <axis xyz="0 1 0"/>
  </joint>

  <link name="wheel_right_link">
    <visual>
      <origin xyz="0 0 0" rpy="0 1.57079633 1.57079633"/>
      <geometry>
        <cylinder radius=".035" length=".025" />
        <!--<mesh filename="package://ros2_tutorial_urdf/meshes/wheels/wheel_assy.dae" scale="1 1 1"/>-->
      </geometry>
      <material name="dark"/>
    </visual>

    <collision>
      <origin xyz="0 0 0" rpy="0 1.57079633 1.57079633"/>
      <geometry>
        <cylinder radius=".035" length=".025" />
        <!--<mesh filename="package://ros2_tutorial_urdf/meshes/wheels/wheel_assy.dae" scale="1 1 1"/>-->
      </geometry>
    </collision>
    <inertial>
      <origin xyz="0 0 0" />
      <mass value="2.8498940e-02" />
      <inertia ixx="1.1175580e-05" ixy="-4.2369783e-11" ixz="-5.9381719e-09"
               iyy="1.1192413e-05" iyz="-1.4400107e-11"
               izz="2.0712558e-05" />
    </inertial>
  </link>

  <joint name="caster_mount_joint" type="continuous">
    <parent link="base_link"/>
    <child link="caster_mount_link"/>
    <origin xyz="-0.10375 0.0 -0.00180" rpy="0 0 0"/>
  </joint>

  <link name="caster_mount_link">
    <visual>
      <origin xyz="0 0 0" rpy="0 0 0"/>
      <geometry>
        <box size=".04 .04 .01"/>
        <!--<mesh filename="package://ros2_tutorial_urdf/meshes/wheels/caster_wheel_mount.dae" scale="1 1 1"/>-->
      </geometry>
      <material name="white"/>
    </visual>
    <collision>
      <origin xyz="0 0 0" rpy="0 0 0"/>
      <geometry>
        <box size=".04 .04 .01"/>
        <!--<mesh filename="package://ros2_tutorial_urdf/meshes/wheels/caster_wheel_mount.dae" scale="1 1 1"/>-->
      </geometry>
    </collision>

    <inertial>
      <origin xyz="0 0 0" />
      <mass value="0.005" />
      <inertia ixx="0.001" ixy="0.0" ixz="0.0"
               iyy="0.001" iyz="0.0"
               izz="0.001" />
    </inertial>
  </link>

  <joint name="caster_rotate_joint" type="continuous"> <!-- continuous -->
    <parent link="caster_mount_link"/>
    <child link="caster_rotate_link"/>
    <origin xyz="0 0 -0.011" rpy="0 0 0"/>
  </joint>

  <link name="caster_rotate_link">
    <visual>
      <origin xyz="0 0 0" rpy="0 0 0"/>
      <geometry>
        <cylinder radius="0.015" length="0.015"/>
        <!--<mesh filename="package://ros2_tutorial_urdf/meshes/wheels/caster_wheel_rotate.dae" scale="1 1 1"/>-->
      </geometry>
      <material name="grey"/>
    </visual>
    <collision>
      <origin xyz="0 0 0" rpy="0 0 0"/>
      <geometry>
        <cylinder radius="0.015" length="0.015"/>
        <!--<mesh filename="package://ros2_tutorial_urdf/meshes/wheels/caster_wheel_rotate.dae" scale="1 1 1"/>-->
      </geometry>
    </collision>

    <inertial>
      <origin xyz="0 0 0" />
      <mass value="0.005" />
      <inertia ixx="0.001" ixy="0.0" ixz="0.0"
               iyy="0.001" iyz="0.0"
               izz="0.001" />
    </inertial>
  </link>

  <joint name="caster_wheel_joint" type="fixed"> <!-- continuous -->
    <parent link="caster_rotate_link"/>
    <child link="caster_wheel_link"/>
    <origin xyz="-0.0115 0 -0.0195" rpy="0 0 0"/>
    <axis xyz="0 1 0"/>
  </joint>

  <link name="caster_wheel_link">
    <visual>
      <origin xyz="0 0 0" rpy="0 1.57079633 1.57079633"/>
      <geometry>
        <cylinder radius=".015" length=".015" />
        <!--<mesh filename="package://ros2_tutorial_urdf/meshes/wheels/caster_wheel.dae" scale="1 1 1"/>-->
      </geometry>
      <material name="dark"/>
    </visual>
    <collision>
      <origin xyz="0 0 0" rpy="0 1.57079633 1.57079633"/>
      <geometry>
        <cylinder radius=".015" length=".015" />
        <!--<mesh filename="package://ros2_tutorial_urdf/meshes/wheels/caster_wheel.dae" scale="1 1 1"/>-->
      </geometry>
    </collision>

    <inertial>
      <origin xyz="0 0 0" />
      <mass value="0.005" />
      <inertia ixx="0.001" ixy="0.0" ixz="0.0"
               iyy="0.001" iyz="0.0"
               izz="0.001" />
    </inertial>
  </link>

  <joint name="imu_joint" type="fixed">
    <parent link="base_link"/>
    <child link="imu_link"/>
    <origin xyz="-0.02 0.01 0.015" rpy="0 0 0"/>
  </joint>

  <link name="imu_link"/>

  <joint name="scan_joint" type="fixed">
    <parent link="base_link"/>
    <child link="base_scan"/>
    <origin xyz="0 0 0.11" rpy="0 0 0"/>
  </joint>

  <link name="base_scan">
    <visual>
      <origin xyz="0 0 .0" rpy="0 0 0"/>
      <geometry>
        <cylinder radius=".035" length=".02" />
        <!--<mesh filename="package://ros2_tutorial_urdf/meshes/sensors/ydlidar_assy.dae" scale="1 1 1"/>-->
      </geometry>
      <material name="blue"/>
    </visual>

    <collision>
      <origin xyz="0 0 .0" rpy="0 0 0"/>
      <geometry>
        <cylinder radius=".035" length=".02" />
        <!--<mesh filename="package://ros2_tutorial_urdf/meshes/sensors/ydlidar_assy.dae" scale="1 1 1"/>-->
      </geometry>
    </collision>

    <inertial>
      <mass value="0.114" />
      <origin xyz="0 0 0" />
      <inertia ixx="0.001" ixy="0.0" ixz="0.0" iyy="0.001" iyz="0.0" izz="0.001" />
    </inertial>
  </link>

</robot>
